<?xml version="1.0" encoding="utf-8"?><testsuites><testsuite name="pytest" errors="0" failures="2" skipped="0" tests="3" time="1.221" timestamp="2022-07-06T21:45:18.362738" hostname="DESKTOP-UCRF95V"><testcase classname="FYP.Test.test_patient.test_patient" name="test_login" file="FYP\Test\test_patient.py" line="29" time="0.024"><failure message="TypeError: test_login() takes 0 positional arguments but 1 was given">self = &lt;unittest.case._Outcome object at 0x000002965D8B42B0&gt;
test_case = &lt;test_patient.test_patient testMethod=test_login&gt;, isTest = True

    @contextlib.contextmanager
    def testPartExecutor(self, test_case, isTest=False):
        old_success = self.success
        self.success = True
        try:
&gt;           yield

C:\Program Files (x86)\Microsoft Visual Studio\Shared\Python39_64\lib\unittest\case.py:59: 
_ _ _ _ _ _ _ _ _ _ _ _ _ _ _ _ _ _ _ _ _ _ _ _ _ _ _ _ _ _ _ _ _ _ _ _ _ _ _ _
C:\Program Files (x86)\Microsoft Visual Studio\Shared\Python39_64\lib\unittest\case.py:592: in run
    self._callTestMethod(testMethod)
_ _ _ _ _ _ _ _ _ _ _ _ _ _ _ _ _ _ _ _ _ _ _ _ _ _ _ _ _ _ _ _ _ _ _ _ _ _ _ _

self = &lt;test_patient.test_patient testMethod=test_login&gt;
method = &lt;bound method test_patient.test_login of &lt;test_patient.test_patient testMethod=test_login&gt;&gt;

    def _callTestMethod(self, method):
&gt;       method()
E       TypeError: test_login() takes 0 positional arguments but 1 was given

C:\Program Files (x86)\Microsoft Visual Studio\Shared\Python39_64\lib\unittest\case.py:550: TypeError</failure><system-out>--------------------------------- Captured Log ---------------------------------

--------------------------------- Captured Out ---------------------------------

</system-out><system-err>--------------------------------- Captured Err ---------------------------------

</system-err></testcase><testcase classname="FYP.Test.test_patient.test_patient" name="test_pass_correct" file="FYP\Test\test_patient.py" line="33" time="0.019"><system-out>--------------------------------- Captured Log ---------------------------------

--------------------------------- Captured Out ---------------------------------

</system-out><system-err>--------------------------------- Captured Err ---------------------------------

</system-err></testcase><testcase classname="FYP.Test.test_patient.test_patient" name="test_pass_incorrect" file="FYP\Test\test_patient.py" line="41" time="0.010"><failure message="AssertionError: False is not true">self = &lt;test_patient.test_patient testMethod=test_pass_incorrect&gt;

    def test_pass_incorrect(self):
        tester = app.test_client(self)
        response = tester.post('/LoginController', data=dict(username = 'wenling', password='password'))
&gt;       self.assertTrue(b'wenling, password' in response.data)
E       AssertionError: False is not true

FYP\Test\test_patient.py:45: AssertionError</failure><system-out>--------------------------------- Captured Log ---------------------------------

--------------------------------- Captured Out ---------------------------------

</system-out><system-err>--------------------------------- Captured Err ---------------------------------

</system-err></testcase></testsuite></testsuites>